<?xml version="1.0" ?>
<robot name="elfin5">
  <link name="gripper_base_link">
    <visual>
      <geometry>
        <mesh filename="file://lebai_lm3_support/meshes/gripper/visual/gripper_base.stl"/>
      </geometry>
      <material name="white">
        <color rgba="0.86 0.85 0.81 1.0"/>
      </material>
    </visual>
    <collision>
      <geometry>
        <mesh filename="file://lebai_lm3_support/meshes/gripper/collision/gripper_base.stl"/>
      </geometry>
    </collision>
    <inertial>
      <mass value="0.1"/>
      <origin rpy="0 0 0" xyz="0 0 0"/>
      <inertia ixx="1e-5" ixy="0" ixz="0" iyy="1e-5" iyz="0" izz="1e-5"/>
    </inertial>
  </link>
  <link name="gripper_r_link1">
    <visual>
      <geometry>
        <mesh filename="file://lebai_lm3_support/meshes/gripper/visual/gripper_link1.stl"/>
      </geometry>
      <material name="white">
        <color rgba="0.86 0.85 0.81 1.0"/>
      </material>
    </visual>
    <collision>
      <geometry>
        <mesh filename="file://lebai_lm3_support/meshes/gripper/collision/gripper_link1.stl"/>
      </geometry>
    </collision>
    <inertial>
      <mass value="0.02"/>
      <origin rpy="0 0 0" xyz="0 0 0"/>
      <inertia ixx="1e-6" ixy="0" ixz="0" iyy="1e-6" iyz="0" izz="1e-6"/>
    </inertial>
  </link>
  <link name="gripper_r_link2">
    <visual>
      <geometry>
        <mesh filename="file://lebai_lm3_support/meshes/gripper/visual/gripper_link2.stl"/>
      </geometry>
      <material name="white">
        <color rgba="0.86 0.85 0.81 1.0"/>
      </material>
    </visual>
    <collision>
      <geometry>
        <mesh filename="file://lebai_lm3_support/meshes/gripper/collision/gripper_link2.stl"/>
      </geometry>
    </collision>
    <inertial>
      <mass value="0.02"/>
      <origin rpy="0 0 0" xyz="0 0 0"/>
      <inertia ixx="1e-6" ixy="0" ixz="0" iyy="1e-6" iyz="0" izz="1e-6"/>
    </inertial>
  </link>
  <link name="gripper_r_link_finger">
    <visual>
      <geometry>
        <mesh filename="file://lebai_lm3_support/meshes/gripper/visual/gripper_link_finger.stl"/>
      </geometry>
      <material name="white">
        <color rgba="0.86 0.85 0.81 1.0"/>
      </material>
    </visual>
    <collision>
      <geometry>
        <mesh filename="file://lebai_lm3_support/meshes/gripper/collision/gripper_link_finger.stl"/>
      </geometry>
    </collision>
    <inertial>
      <mass value="0.03"/>
      <origin rpy="0 0 0" xyz="0 0 0"/>
      <inertia ixx="1e-6" ixy="0" ixz="0" iyy="1e-6" iyz="0" izz="1e-6"/>
    </inertial>
  </link>
  <link name="gripper_l_link1">
    <visual>
      <geometry>
        <mesh filename="file://lebai_lm3_support/meshes/gripper/visual/gripper_link1.stl"/>
      </geometry>
      <material name="white">
        <color rgba="0.86 0.85 0.81 1.0"/>
      </material>
    </visual>
    <collision>
      <geometry>
        <mesh filename="file://lebai_lm3_support/meshes/gripper/collision/gripper_link1.stl"/>
      </geometry>
    </collision>
    <inertial>
      <mass value="0.02"/>
      <origin rpy="0 0 0" xyz="0 0 0"/>
      <inertia ixx="1e-6" ixy="0" ixz="0" iyy="1e-6" iyz="0" izz="1e-6"/>
    </inertial>
  </link>
  <link name="gripper_l_link2">
    <visual>
      <geometry>
        <mesh filename="file://lebai_lm3_support/meshes/gripper/visual/gripper_link2.stl"/>
      </geometry>
      <material name="white">
        <color rgba="0.86 0.85 0.81 1.0"/>
      </material>
    </visual>
    <collision>
      <geometry>
        <mesh filename="file://lebai_lm3_support/meshes/gripper/collision/gripper_link2.stl"/>
      </geometry>
    </collision>
    <inertial>
      <mass value="0.02"/>
      <origin rpy="0 0 0" xyz="0 0 0"/>
      <inertia ixx="1e-6" ixy="0" ixz="0" iyy="1e-6" iyz="0" izz="1e-6"/>
    </inertial>
  </link>
  <link name="gripper_l_link_finger">
    <visual>
      <geometry>
        <mesh filename="file://lebai_lm3_support/meshes/gripper/visual/gripper_link_finger.stl"/>
      </geometry>
      <material name="white">
        <color rgba="0.86 0.85 0.81 1.0"/>
      </material>
    </visual>
    <collision>
      <geometry>
        <mesh filename="file://lebai_lm3_support/meshes/gripper/collision/gripper_link_finger.stl"/>
      </geometry>
    </collision>
    <inertial>
      <mass value="0.03"/>
      <origin rpy="0 0 0" xyz="0 0 0"/>
      <inertia ixx="1e-6" ixy="0" ixz="0" iyy="1e-6" iyz="0" izz="1e-6"/>
    </inertial>
  </link>
  <link name="gripper_tip"/>

  <joint name="gripper_r_joint1" type="revolute">
    <parent link="gripper_base_link"/>
    <child link="gripper_r_link1"/>
    <origin rpy="1.570796327 0.0 3.141592653589793" xyz="0.025 0.0 0.0856"/>
    <axis xyz="0 0 1"/>
    <limit effort="35" lower="0.0" upper="1.0" velocity="1"/>
  </joint>
  
  <joint name="gripper_r_joint2" type="revolute">
    <parent link="gripper_base_link"/>
    <child link="gripper_r_link2"/>
    <origin rpy="1.570796327 0 0" xyz="0.0115 0.0 0.1056"/>
    <axis xyz="0 0 1"/>
    <limit effort="35" lower="0.0" upper="1.0" velocity="1"/>
    <mimic joint="gripper_r_joint1" multiplier="-1.0" offset="0.0"/>
  </joint>
  
  <joint name="gripper_r_joint_finger" type="revolute">
    <parent link="gripper_r_link2"/> 
    <child link="gripper_r_link_finger"/>
    <origin rpy="3.141592653589793 0 3.141592653589793" xyz="0.0 0.053 0.0"/>
    <axis xyz="0 0 1"/>
    <limit effort="35" lower="-10" upper="10" velocity="1"/>
    <mimic joint="gripper_r_joint1" multiplier="-1.0" offset="0.0"/>
  </joint>

  <joint name="gripper_l_joint1" type="revolute">
    <parent link="gripper_base_link"/>
    <child link="gripper_l_link1"/>
    <origin rpy="1.570796327 0.0 0.0" xyz="-0.025 0.0 0.0856"/>
    <axis xyz="0 0 1"/>
    <limit effort="35" lower="0.0" upper="1.0" velocity="1"/>
    </joint>
  
  <joint name="gripper_l_joint2" type="revolute">
    <parent link="gripper_base_link"/>
    <child link="gripper_l_link2"/>
    <origin rpy="1.570796327 0 3.141592653589793" xyz="-0.0115 0.0 0.1056"/>
    <axis xyz="0 0 1"/>
    <limit effort="35" lower="0.0" upper="1.0" velocity="1"/>
    <mimic joint="gripper_l_joint1" multiplier="-1.0" offset="0.0"/>
  </joint>

  <joint name="gripper_l_joint_finger" type="revolute">
    <parent link="gripper_l_link2"/>
    <child link="gripper_l_link_finger"/>
    <origin rpy="3.141592653589793 0 3.141592653589793" xyz="0.0 0.053 0.0"/>
    <axis xyz="0 0 1"/>
    <limit effort="35" lower="-10" upper="10" velocity="1"/>
    <mimic joint="gripper_l_joint1" multiplier="-1.0" offset="0.0"/>
  </joint>
  
  <joint name="gripper_joint_tip" type="fixed">
    <parent link="gripper_l_link_finger"/>
    <child link="gripper_tip"/>
    <origin rpy="0.0 0.0 0.0" xyz="0.0115 0.0 0.0"/>
  </joint>

  <material name="black">
    <color rgba="0.0 0.0 0.0 1.0"/>
  </material>
  <material name="blue">
    <color rgba="0.0 0.0 0.8 1.0"/>
  </material>
  <material name="green">
    <color rgba="0.0 0.8 0.0 1.0"/>
  </material>
  <material name="grey">
    <color rgba="0.2 0.2 0.2 1.0"/>
  </material>
  <material name="orange">
    <color rgba="1.0 0.4235294117647059 0.0392156862745098 1.0"/>
  </material>
  <material name="brown">
    <color rgba="0.8705882352941177 0.8117647058823529 0.7647058823529411 1.0"/>
  </material>
  <material name="red">
    <color rgba="0.8 0.0 0.0 1.0"/>
  </material>
  <material name="white">
    <color rgba="1.0 1.0 1.0 1.0"/>
  </material>
  <material name="metal">
    <color rgba="0.768627450980392 0.749019607843137 0.729411764705882 1"/>
  </material>
  <material name="metal_grey">
    <color rgba="0.501960784313725 0.501960784313725 0.501960784313725 1"/>
  </material>
  <material name="metal_white">
    <color rgba="0.866666666666667 0.866666666666667 0.890196078431373 1"/>
  </material>
  <!-- ros_control plugin -->
  <gazebo>
    <plugin filename="libgazebo_ros_control.so" name="gazebo_ros_control">
      <robotSimType>gazebo_ros_control/DefaultRobotHWSim</robotSimType>
      <legacyModeNS>true</legacyModeNS>
    </plugin>
  </gazebo>
  <gazebo reference="elfin_link2">
    <visual name="visual">
      <material>
        <script>
          <uri>file://media/materials/scripts/gazebo.material</uri>
          <name>Gazebo/Grey</name>
        </script>
      </material>
    </visual>
  </gazebo>
  <gazebo reference="elfin_link4">
    <visual name="visual">
      <material>
        <script>
          <uri>file://media/materials/scripts/gazebo.material</uri>
          <name>Gazebo/Grey</name>
        </script>
      </material>
    </visual>
  </gazebo>
  <transmission name="elfin_joint1_trans">
    <type>transmission_interface/SimpleTransmission</type>
    <joint name="elfin_joint1">
      <hardwareInterface>hardware_interface/PositionJointInterface</hardwareInterface>
    </joint>
    <actuator name="elfin_joint1_motor">
      <mechanicalReduction>1</mechanicalReduction>
    </actuator>
  </transmission>
  <transmission name="elfin_joint2_trans">
    <type>transmission_interface/SimpleTransmission</type>
    <joint name="elfin_joint2">
      <hardwareInterface>hardware_interface/PositionJointInterface</hardwareInterface>
    </joint>
    <actuator name="elfin_joint2_motor">
      <mechanicalReduction>1</mechanicalReduction>
    </actuator>
  </transmission>
  <transmission name="elfin_joint3_trans">
    <type>transmission_interface/SimpleTransmission</type>
    <joint name="elfin_joint3">
      <hardwareInterface>hardware_interface/PositionJointInterface</hardwareInterface>
    </joint>
    <actuator name="elfin_joint3_motor">
      <mechanicalReduction>1</mechanicalReduction>
    </actuator>
  </transmission>
  <transmission name="elfin_joint4_trans">
    <type>transmission_interface/SimpleTransmission</type>
    <joint name="elfin_joint4">
      <hardwareInterface>hardware_interface/PositionJointInterface</hardwareInterface>
    </joint>
    <actuator name="elfin_joint4_motor">
      <mechanicalReduction>1</mechanicalReduction>
    </actuator>
  </transmission>
  <transmission name="elfin_joint5_trans">
    <type>transmission_interface/SimpleTransmission</type>
    <joint name="elfin_joint5">
      <hardwareInterface>hardware_interface/PositionJointInterface</hardwareInterface>
    </joint>
    <actuator name="elfin_joint5_motor">
      <mechanicalReduction>1</mechanicalReduction>
    </actuator>
  </transmission>
  <transmission name="elfin_joint6_trans">
    <type>transmission_interface/SimpleTransmission</type>
    <joint name="elfin_joint6">
      <hardwareInterface>hardware_interface/PositionJointInterface</hardwareInterface>
    </joint>
    <actuator name="elfin_joint6_motor">
      <mechanicalReduction>1</mechanicalReduction>
    </actuator>
  </transmission>
  <link name="world"/>
  <joint name="world_base" type="fixed">
    <origin rpy="0 0 0" xyz="0 0 0"/>
    <parent link="world"/>
    <child link="elfin_base_link"/>
  </joint>
  <link name="elfin_base_link"/>
  <joint name="elfin_base_joint" type="fixed">
    <origin rpy="0 0 1.5707963267948966" xyz="0 0 0"/>
    <parent link="elfin_base_link"/>
    <child link="elfin_base"/>
  </joint>
  <link name="elfin_base">
    <inertial>
      <origin rpy="0 0 0" xyz="0.00022102 0.0013404 0.025529"/>
      <mass value="2.13370989"/>
      <inertia ixx="0.0040358799" ixy="0.00017551199999999998" ixz="5.840099999999999e-06" iyy="0.0041550303" iyz="3.38355e-05" izz="0.007080395099999999"/>
    </inertial>
    <visual>
      <origin rpy="0 0 0" xyz="0 0 0"/>
      <geometry>
        <mesh filename="file://elfin_description/meshes/elfin5/elfin_base.STL"/>
      </geometry>
      <material name="metal_white"/>
    </visual>
    <collision>
      <origin rpy="0 0 0" xyz="0 0 0"/>
      <geometry>
        <mesh filename="file://elfin_description/meshes/elfin5/elfin_base.STL"/>
      </geometry>
    </collision>
  </link>
  <link name="elfin_link1">
    <inertial>
      <origin rpy="0 0 0" xyz="-0.021815 -1.1609E-05 0.095394"/>
      <mass value="7.96222548"/>
      <inertia ixx="0.0401380494" ixy="0.0088981494" ixz="-3.0899999999999996e-06" iyy="0.0222824535" iyz="-1.6068e-06" izz="0.047360831699999995"/>
    </inertial>
    <visual>
      <origin rpy="0 0 0" xyz="0 0 0"/>
      <geometry>
        <mesh filename="file://elfin_description/meshes/elfin5/elfin_link1.STL"/>
      </geometry>
      <material name="metal"/>
    </visual>
    <collision>
      <origin rpy="0 0 0" xyz="0 0 0"/>
      <geometry>
        <mesh filename="file://elfin_description/meshes/elfin5/elfin_link1.STL"/>
      </geometry>
    </collision>
  </link>
  <joint name="elfin_joint1" type="revolute">
    <origin rpy="0 0 0" xyz="0 0 0.0735"/>
    <parent link="elfin_base"/>
    <child link="elfin_link1"/>
    <axis xyz="0 0 1"/>
    <limit effort="200" lower="-3.14" upper="3.14" velocity="1.57"/>
  </joint>
  <link name="elfin_link2">
    <inertial>
      <origin rpy="0 0 0" xyz="-0.15508 0.031021 0.052499"/>
      <mass value="3.73459563"/>
      <inertia ixx="0.091957473" ixy="-0.0039070269" ixz="-7.415999999999999e-07" iyy="0.005196020399999999" iyz="-6.488999999999999e-06" izz="0.0909910446"/>
    </inertial>
    <visual>
      <origin rpy="0 0 0" xyz="0 0 0"/>
      <geometry>
        <mesh filename="file://elfin_description/meshes/elfin5/elfin_link2.STL"/>
      </geometry>
      <material name="metal_grey"/>
    </visual>
    <collision>
      <origin rpy="0 0 0" xyz="0 0 0"/>
      <geometry>
        <mesh filename="file://elfin_description/meshes/elfin5/elfin_link2.STL"/>
      </geometry>
    </collision>
  </link>
  <joint name="elfin_joint2" type="revolute">
    <origin rpy="1.5708 1.3734 -1.5708" xyz="-0.078 0 0.1465"/>
    <parent link="elfin_link1"/>
    <child link="elfin_link2"/>
    <axis xyz="0 0 1"/>
    <limit effort="200" lower="-2.35" upper="2.35" velocity="1.57"/>
  </joint>
  <link name="elfin_link3">
    <inertial>
      <origin rpy="0 0 0" xyz="1.1184E-05 0.041481 -0.052586"/>
      <mass value="4.71497847"/>
      <inertia ixx="0.0163101015" ixy="0.003836235" ixz="-5.562e-07" iyy="0.0098219049" iyz="-2.0703e-06" izz="0.0201630843"/>
    </inertial>
    <visual>
      <origin rpy="0 0 0" xyz="0 0 0"/>
      <geometry>
        <mesh filename="file://elfin_description/meshes/elfin5/elfin_link3.STL"/>
      </geometry>
      <material name="metal"/>
    </visual>
    <collision>
      <origin rpy="0 0 0" xyz="0 0 0"/>
      <geometry>
        <mesh filename="file://elfin_description/meshes/elfin5/elfin_link3.STL"/>
      </geometry>
    </collision>
  </link>
  <joint name="elfin_joint3" type="revolute">
    <origin rpy="0 0 1.3734" xyz="-0.37262 0.074541 -0.0060028"/>
    <parent link="elfin_link2"/>
    <child link="elfin_link3"/>
    <axis xyz="0 0 -1"/>
    <limit effort="200" lower="-2.61" upper="2.61" velocity="1.57"/>
  </joint>
  <link name="elfin_link4">
    <inertial>
      <origin rpy="0 0 0" xyz="-0.058961 3.7945E-05 0.13807"/>
      <mass value="1.46783034"/>
      <inertia ixx="0.0167614269" ixy="0.004792342799999999" ixz="-1.6377e-06" iyy="0.004072002" iyz="6.025499999999999e-06" izz="0.0187714101"/>
    </inertial>
    <visual>
      <origin rpy="0 0 0" xyz="0 0 0"/>
      <geometry>
        <mesh filename="file://elfin_description/meshes/elfin5/elfin_link4.STL"/>
      </geometry>
      <material name="metal_grey"/>
    </visual>
    <collision>
      <origin rpy="0 0 0" xyz="0 0 0"/>
      <geometry>
        <mesh filename="file://elfin_description/meshes/elfin5/elfin_link4.STL"/>
      </geometry>
    </collision>
  </link>
  <joint name="elfin_joint4" type="revolute">
    <origin rpy="0 1.5708 1.5708" xyz="0 0.119 -0.072"/>
    <parent link="elfin_link3"/>
    <child link="elfin_link4"/>
    <axis xyz="0 0 1"/>
    <limit effort="104" lower="-3.14" upper="3.14" velocity="1.57"/>
  </joint>
  <link name="elfin_link5">
    <inertial>
      <origin rpy="0 0 0" xyz="3.4043E-06 -0.036593 -0.044531"/>
      <mass value="2.49795291"/>
      <inertia ixx="0.0060069291" ixy="0.0014650925999999999" ixz="3.09e-08" iyy="0.0034992704999999994" iyz="-3.7079999999999996e-07" izz="0.0076218249"/>
    </inertial>
    <visual>
      <origin rpy="0 0 0" xyz="0 0 0"/>
      <geometry>
        <mesh filename="file://elfin_description/meshes/elfin5/elfin_link5.STL"/>
      </geometry>
      <material name="metal"/>
    </visual>
    <collision>
      <origin rpy="0 0 0" xyz="0 0 0"/>
      <geometry>
        <mesh filename="file://elfin_description/meshes/elfin5/elfin_link5.STL"/>
      </geometry>
    </collision>
  </link>
  <joint name="elfin_joint5" type="revolute">
    <origin rpy="-1.5708 0 1.5708" xyz="-0.0605 0 0.301"/>
    <parent link="elfin_link4"/>
    <child link="elfin_link5"/>
    <axis xyz="0 0 -1"/>
    <limit effort="34" lower="-2.56" upper="2.56" velocity="1.57"/>
  </joint>
  <link name="elfin_link6">
    <inertial>
      <origin rpy="0 0 0" xyz="-0.007255 -3.2028E-05 0.033062"/>
      <mass value="0.45519408"/>
      <inertia ixx="0.0005996762999999999" ixy="4.326e-06" ixz="-8.9301e-06" iyy="0.0006053928" iyz="1.545e-07" izz="0.0006024263999999999"/>
    </inertial>
    <visual>
      <origin rpy="0 0 0" xyz="0 0 0"/>
      <geometry>
        <mesh filename="file://elfin_description/meshes/elfin5/elfin_link6.STL"/>
      </geometry>
      <material name="metal_white"/>
    </visual>
    <collision>
      <origin rpy="0 0 0" xyz="0 0 0"/>
      <geometry>
        <mesh filename="file://elfin_description/meshes/elfin5/elfin_link6.STL"/>
      </geometry>
    </collision>
  </link>
  <joint name="elfin_joint6" type="revolute">
    <origin rpy="1.5708 1.5708 0" xyz="0 -0.1005 -0.0605"/>
    <parent link="elfin_link5"/>
    <child link="elfin_link6"/>
    <axis xyz="0 0 1"/>
    <limit effort="34" lower="-3.14" upper="3.14" velocity="1.57"/>
  </joint>
  <link name="elfin_end_link"/>
  <joint name="elfin_end_joint" type="fixed">
    <origin rpy="0 0 -1.5708" xyz="0 0 0.0545"/>
    <parent link="elfin_link6"/>
    <child link="elfin_end_link"/>
  </joint>
  <link name="elfin_dummy_gripper"/>
  <joint name="elfin_dummy_joint" type="fixed">
    <origin rpy="1.5707963267948966 1.5707963267948966 0" xyz="0 -0.0935 0"/>
    <parent link="elfin_link6"/>
    <child link="elfin_dummy_gripper"/>
  </joint>
  <joint name="arm_to_gripper_joint" type="fixed">
    <parent link="elfin_end_link"/>
    <child link="gripper_base_link"/>
    <origin xyz="0 0 0" rpy="0 0 0"/>
  </joint>
</robot>
