<?xml version="1.0" ?>
<robot name="lebai_lm3">
  <link name="world"/>
  <!-- link list -->
  <link name="gripper_base_link">
    <visual>
      <geometry>
        <mesh filename="file://lebai_lm3_support/meshes/gripper/visual/gripper_base.stl"/>
      </geometry>
      <material name="white">
        <color rgba="0.86 0.85 0.81 1.0"/>
      </material>
    </visual>
    <collision>
      <geometry>
        <mesh filename="file://lebai_lm3_support/meshes/gripper/collision/gripper_base.stl"/>
      </geometry>
    </collision>
  </link>
  <link name="gripper_r_link1">
    <visual>
      <geometry>
        <mesh filename="file://lebai_lm3_support/meshes/gripper/visual/gripper_link1.stl"/>
      </geometry>
      <material name="white">
        <color rgba="0.86 0.85 0.81 1.0"/>
      </material>
    </visual>
    <collision>
      <geometry>
        <mesh filename="file://lebai_lm3_support/meshes/gripper/collision/gripper_link1.stl"/>
      </geometry>
    </collision>
  </link>
  <link name="gripper_r_link2">
    <visual>
      <geometry>
        <mesh filename="file://lebai_lm3_support/meshes/gripper/visual/gripper_link2.stl"/>
      </geometry>
      <material name="white">
        <color rgba="0.86 0.85 0.81 1.0"/>
      </material>
    </visual>
    <collision>
      <geometry>
        <mesh filename="file://lebai_lm3_support/meshes/gripper/collision/gripper_link2.stl"/>
      </geometry>
    </collision>
  </link>
  <link name="gripper_r_link_finger">
    <visual>
      <geometry>
        <mesh filename="file://lebai_lm3_support/meshes/gripper/visual/gripper_link_finger.stl"/>
      </geometry>
      <material name="white">
        <color rgba="0.86 0.85 0.81 1.0"/>
      </material>
    </visual>
    <collision>
      <geometry>
        <mesh filename="file://lebai_lm3_support/meshes/gripper/collision/gripper_link_finger.stl"/>
      </geometry>
    </collision>
  </link>
  <link name="gripper_l_link1">
    <visual>
      <geometry>
        <mesh filename="file://lebai_lm3_support/meshes/gripper/visual/gripper_link1.stl"/>
      </geometry>
      <material name="white">
        <color rgba="0.86 0.85 0.81 1.0"/>
      </material>
    </visual>
    <collision>
      <geometry>
        <mesh filename="file://lebai_lm3_support/meshes/gripper/collision/gripper_link1.stl"/>
      </geometry>
    </collision>
  </link>
  <link name="gripper_l_link2">
    <visual>
      <geometry>
        <mesh filename="file://lebai_lm3_support/meshes/gripper/visual/gripper_link2.stl"/>
      </geometry>
      <material name="white">
        <color rgba="0.86 0.85 0.81 1.0"/>
      </material>
    </visual>
    <collision>
      <geometry>
        <mesh filename="file://lebai_lm3_support/meshes/gripper/collision/gripper_link2.stl"/>
      </geometry>
    </collision>
  </link>
  <link name="gripper_l_link_finger">
    <visual>
      <geometry>
        <mesh filename="file://lebai_lm3_support/meshes/gripper/visual/gripper_link_finger.stl"/>
      </geometry>
      <material name="white">
        <color rgba="0.86 0.85 0.81 1.0"/>
      </material>
    </visual>
    <collision>
      <geometry>
        <mesh filename="file://lebai_lm3_support/meshes/gripper/collision/gripper_link_finger.stl"/>
      </geometry>
    </collision>
  </link>
  <link name="gripper_tip"/>
  <!-- end of link list -->
  <!-- joint list -->
  <joint name="gripper_r_joint1" type="revolute">
    <parent link="gripper_base_link"/>
    <child link="gripper_r_link1"/>
    <origin rpy="1.570796327 0.0 3.141592653589793" xyz="0.025 0.0 0.0856"/>
    <axis xyz="0 0 1"/>
    <limit effort="100" lower="-10.0" upper="10.0" velocity="1"/>
  </joint>
  <joint name="gripper_r_joint2" type="revolute">
    <parent link="gripper_base_link"/>
    <child link="gripper_r_link2"/>
    <origin rpy="1.570796327 0 0" xyz="0.0115 0.0 0.1056"/>
    <axis xyz="0 0 1"/>
    <limit effort="100" lower="-10.0" upper="10.0" velocity="1"/>
  </joint>
  <joint name="gripper_r_joint_finger" type="revolute">
    <parent link="gripper_r_link2"/>
    <child link="gripper_r_link_finger"/>
    <origin rpy="3.141592653589793 0 3.141592653589793" xyz="0.0 0.053 0.0"/>
    <axis xyz="0 0 1"/>
    <limit effort="100" lower="-10" upper="10" velocity="1"/>
  </joint>
  <joint name="gripper_l_joint1" type="revolute">
    <parent link="gripper_base_link"/>
    <child link="gripper_l_link1"/>
    <origin rpy="1.570796327 0.0 0.0" xyz="-0.025 0.0 0.0856"/>
    <axis xyz="0 0 1"/>
    <limit effort="100" lower="-10.0" upper="10.0" velocity="1"/>
  </joint>
  <joint name="gripper_l_joint2" type="revolute">
    <parent link="gripper_base_link"/>
    <child link="gripper_l_link2"/>
    <origin rpy="1.570796327 0 3.141592653589793" xyz="-0.0115 0.0 0.1056"/>
    <axis xyz="0 0 1"/>
    <limit effort="100" lower="-10.0" upper="10.0" velocity="1"/>
  </joint>
  <joint name="gripper_l_joint_finger" type="revolute">
    <parent link="gripper_l_link2"/>
    <child link="gripper_l_link_finger"/>
    <origin rpy="3.141592653589793 0 3.141592653589793" xyz="0.0 0.053 0.0"/>
    <axis xyz="0 0 1"/>
    <limit effort="100" lower="-10" upper="10" velocity="1"/>
  </joint>
  <joint name="gripper_joint_tip" type="fixed">
    <parent link="gripper_l_link_finger"/>
    <child link="gripper_tip"/>
    <origin rpy="0.0 0.0 0.0" xyz="0.0115 0.0 0.0"/>
  </joint>
  <joint name="fixed" type="fixed">
    <parent link="world"/>
    <child link="gripper_base_link"/>
  </joint>
</robot>
